Workbook

Sheet Inlets
A1: Station | B1: Type | C1: Location | D1: Bypass | E1: Curb Length | F1: Curb Height | G1: Grate Area | H1: Grate Width | I1: Grate Length | J1: Capacity | K1: Sx | L1: Sw | M1: Depression | N1: Gutter Width | O1: Longitudinal Slope | P1: n Value | Q1: Structure Shape | R1: Structure Length | S1: Structure Width | T1: Standard Detail | U1: Invert | V1: Rim
A2: 111+64 LT. | B2: Curb Inlet | C2: on grade | E2: 0 | F2: 4 | G2: =H2*I2 -> 0 | H2: 0 | I2: 0 | K2: 0.02 | L2: 0.05 | M2: 2 | N2: 1 | O2: 0.0075 | P2: 0.013 | Q2: Circular | R2: 3 | S2: 3 | T2: 0 | U2: 1275 | V2: 1280
A3: 111+65 RT. | B3: Curb Inlet | C3: on grade | E3: 0 | F3: 4 | G3: =H3*I3 -> 0 | H3: 0 | I3: 0 | K3: 0.02 | L3: 0.05 | M3: 2 | N3: 1 | O3: 0.0075 | P3: 0.013 | Q3: Circular | R3: 3 | S3: 3 | T3: 0 | U3: 1274.47 | V3: 1279.07
A4: 112+35 LT. | B4: Curb Inlet | C4: on grade | D4: 111+64 LT. | E4: 0 | F4: 4 | G4: =H4*I4 -> 0 | H4: 0 | I4: 0 | K4: 0.02 | L4: 0.05 | M4: 2 | N4: 1 | O4: 0.0075 | P4: 0.013 | Q4: Circular | R4: 3 | S4: 3 | T4: 0 | U4: 1280 | V4: 1276
A5: 112+35 RT. | B5: Curb Inlet | C5: on grade | D5: 111+65 RT. | E5: 4 | F5: 4 | G5: =H5*I5 -> 0 | H5: 0 | I5: 0 | K5: 0.02 | L5: 0.05 | M5: 2 | N5: 1 | O5: 0.0075 | P5: 0.013 | Q5: Circular | R5: 4 | S5: 0 | T5: MO | U5: 1275.14 | V5: 1279.48
A6: 113+00 RT. | B6: Curb Inlet | C6: on grade | D6: 112+35 RT. | E6: 4 | F6: 4 | G6: =H6*I6 -> 0 | H6: 0 | I6: 0 | K6: 0.02 | L6: 0.05 | M6: 2 | N6: 1 | O6: 0.0075 | P6: 0.013 | Q6: Circular | R6: 4 | S6: 0 | T6: MO | U6: 1275.75 | V6: 1279.9
A7: 113+78 LT. | B7: Grate Inlet | C7: on grade | D7: 112+35 LT. | E7: 4 | F7: 0 | G7: =H7*I7 -> 6 | H7: 2 | I7: 3 | K7: 0.02 | L7: 0.05 | M7: 0 | N7: 1 | O7: 0.0075 | P7: 0.013 | Q7: Rectangular | R7: 4 | S7: 4 | T7: ST | U7: 1276 | V7: 1280.39
A8: 115+24 LT. | B8: Curb Inlet | C8: on grade | D8: 207+99 LT. | E8: 12 | F8: 4 | G8: =H8*I8 -> 0 | H8: 0 | I8: 0 | K8: 0.02 | L8: 0.05 | M8: 2 | N8: 1 | O8: 0.0122 | P8: 0.013 | Q8: Circular | R8: 4 | S8: 0 | T8: MO | U8: 1274.1 | V8: 1279.63
A9: 115+42 LT. | B9: Grate Inlet | C9: sag | E9: 4 | F9: 0 | G9: =H9*I9 -> 6 | H9: 2 | I9: 3 | K9: 0.02 | L9: 0.05 | M9: 0 | N9: 1 | O9: 0.0122 | P9: 0.013 | Q9: Rectangular | R9: 4 | S9: 4 | T9: E | U9: 1275.82 | V9: 1279.4
A10: 115+66 LT. | B10: Curb Inlet | C10: on grade | D10: 115+24 LT. | E10: 4 | F10: 4 | G10: =H10*I10 -> 0 | H10: 0 | I10: 0 | K10: 0.02 | L10: 0.05 | M10: 2 | N10: 1 | O10: 0.0122 | P10: 0.013 | Q10: Circular | R10: 4 | S10: 0 | T10: MO | U10: 1275.13 | V10: 1280.24
A11: 115+90 RT. | B11: Curb Inlet | C11: on grade | D11: 115+66 RT. | E11: 5 | F11: 4 | G11: =H11*I11 -> 0 | H11: 0 | I11: 0 | K11: 0.02 | L11: 0.05 | M11: 2 | N11: 1 | O11: 0.0122 | P11: 0.013 | Q11: Circular | R11: 5 | S11: 0 | T11: MO | U11: 1275.62 | V11: 1281.03
A12: 116+00 RT. | B12: Curb Inlet | C12: on grade | D12: 115+90 RT. | E12: 5 | F12: 4 | G12: =H12*I12 -> 0 | H12: 0 | I12: 0 | K12: 0.02 | L12: 0.05 | M12: 2 | N12: 1 | O12: 0.0122 | P12: 0.013 | Q12: Circular | R12: 5 | S12: 0 | T12: MO | U12: 1275.69 | V12: 1281.13
A13: 116+25 LT. | B13: Curb Inlet | C13: on grade | D13: 115+66 LT. | E13: 4 | F13: 4 | G13: =H13*I13 -> 0 | H13: 0 | I13: 0 | K13: 0.02 | L13: 0.05 | M13: 2 | N13: 1 | O13: 0.0122 | P13: 0.013 | Q13: Circular | R13: 4 | S13: 0 | T13: MO | U13: 1276.31 | V13: 1281.22
A14: 117+85 RT. | B14: Curb Inlet | C14: on grade | D14: 116+00 RT. | E14: 5 | F14: 4 | G14: =H14*I14 -> 0 | H14: 0 | I14: 0 | K14: 0.02 | L14: 0.05 | M14: 2 | N14: 1 | O14: 0.0122 | P14: 0.013 | Q14: Circular | R14: 5 | S14: 0 | T14: MO | U14: 1278.04 | V14: 1283.99
A15: 118+25 LT. | B15: Curb Inlet | C15: on grade | D15: 117+85 LT. | E15: 4 | F15: 4 | G15: =H15*I15 -> 0 | H15: 0 | I15: 0 | K15: 0.02 | L15: 0.05 | M15: 2 | N15: 1 | O15: 0.0349 | P15: 0.013 | Q15: Circular | R15: 4 | S15: 0 | T15: MO | U15: 1280.28 | V15: 1284.45
A16: 120+50 LT. | B16: Curb Inlet | C16: on grade | D16: 118+25 LT. | E16: 4 | F16: 4 | G16: =H16*I16 -> 0 | H16: 0 | I16: 0 | K16: 0.02 | L16: 0.05 | M16: 2 | N16: 1 | O16: 0.0349 | P16: 0.013 | Q16: Circular | R16: 4 | S16: 0 | T16: MO | U16: 1287.67 | V16: 1291.59
A17: 120+50 RT. | B17: Curb Inlet | C17: on grade | D17: 117+85 RT. | E17: 4 | F17: 4 | G17: =H17*I17 -> 0 | H17: 0 | I17: 0 | K17: 0.02 | L17: 0.05 | M17: 2 | N17: 1 | O17: 0.0349 | P17: 0.013 | Q17: Circular | R17: 4 | S17: 0 | T17: MO | U17: 1288.26 | V17: 1291.94
A18: 122+11 RT. | B18: Curb Inlet | C18: on grade | D18: 120+50 RT. | E18: 0 | F18: 4 | G18: =H18*I18 -> 0 | H18: 0 | I18: 0 | K18: 0.02 | L18: 0.05 | M18: 2 | N18: 1 | O18: 0.0349 | P18: 0.013 | Q18: Circular | R18: 3 | S18: 3 | T18: 0 | U18: 1290 | V18: 1295
A19: 124+50 LT. | B19: Curb Inlet | C19: on grade | D19: 120+50 LT. | E19: 4 | F19: 4 | G19: =H19*I19 -> 0 | H19: 0 | I19: 0 | K19: 0.02 | L19: 0.05 | M19: 2 | N19: 1 | O19: 0.0349 | P19: 0.013 | Q19: Circular | R19: 4 | S19: 0 | T19: MO | U19: 1290.74 | V19: 1294.35
A20: 200+19 LT. | B20: Curb Inlet | C20: on grade | D20: 203+48 LT. | E20: 4 | F20: 4 | G20: =H20*I20 -> 0 | H20: 0 | I20: 0 | K20: 0.02 | L20: 0.05 | M20: 2 | N20: 1 | O20: 0.003 | P20: 0.013 | Q20: Circular | R20: 4 | S20: 0 | T20: MO | U20: 1277.09 | V20: 1280.64
A21: 200+19 RT. | B21: Curb Inlet | C21: on grade | D21: 203+48 RT. | E21: 0 | F21: 4 | G21: =H21*I21 -> 0 | H21: 0 | I21: 0 | K21: 0.02 | L21: 0.05 | M21: 2 | N21: 1 | O21: 0.003 | P21: 0.013 | Q21: Circular | R21: 3 | S21: 3 | T21: 0 | U21: 1272.67 | V21: 1276.77
A22: 203+48 LT. | B22: Curb Inlet | C22: on grade | D22: 204+20 LT. | E22: 7 | F22: 4 | G22: =H22*I22 -> 0 | H22: 0 | I22: 0 | K22: 0.02 | L22: 0.05 | M22: 2 | N22: 1 | O22: 0.003 | P22: 0.013 | Q22: Circular | R22: 7 | S22: 5 | T22: C | U22: 1271.55 | V22: 1278.44
A23: 203+48 RT. | B23: Curb Inlet | C23: on grade | D23: 204+09 RT. | E23: 7 | F23: 4 | G23: =H23*I23 -> 0 | H23: 0 | I23: 0 | K23: 0.02 | L23: 0.05 | M23: 2 | N23: 1 | O23: 0.003 | P23: 0.013 | Q23: Circular | R23: 7 | S23: 7 | T23: C | U23: 1271.2 | V23: 1278.64
A24: 204+09 RT. | B24: Curb Inlet | C24: sag | E24: 0 | F24: 4 | G24: =H24*I24 -> 0 | H24: 0 | I24: 0 | K24: 0.02 | L24: 0.05 | M24: 2 | N24: 1 | P24: 0.013 | Q24: Circular | R24: 3 | S24: 3 | T24: 0 | U24: 1272.99 | V24: 1278.53
A25: 204+20 LT. | B25: Curb Inlet | C25: sag | E25: 6 | F25: 4 | G25: =H25*I25 -> 0 | H25: 0 | I25: 0 | K25: 0.02 | L25: 0.05 | M25: 2 | N25: 1 | P25: 0.013 | Q25: Circular | R25: 6 | S25: 0 | T25: MO | U25: 1271.88 | V25: 1278.3
A26: 204+30 LT. | B26: Curb Inlet | C26: on grade | D26: 204+20 LT. | E26: 6 | F26: 4 | G26: =H26*I26 -> 0 | H26: 0 | I26: 0 | K26: 0.02 | L26: 0.05 | M26: 2 | N26: 1 | O26: 0.0059 | P26: 0.013 | Q26: Circular | R26: 6 | S26: 0 | T26: MO | U26: 1271.9 | V26: 1278.3
A27: 204+62 LT. | B27: Curb Inlet | C27: on grade | D27: 204+30 LT. | E27: 6 | F27: 4 | G27: =H27*I27 -> 0 | H27: 0 | I27: 0 | K27: 0.02 | L27: 0.05 | M27: 2 | N27: 1 | O27: 0.0059 | P27: 0.013 | Q27: Circular | R27: 6 | S27: 0 | T27: MO | U27: 1272.03 | V27: 1278.33
A28: 204+67 RT. | B28: Curb Inlet | C28: on grade | D28: 204+09 RT. | E28: 0 | F28: 4 | G28: =H28*I28 -> 0 | H28: 0 | I28: 0 | K28: 0.02 | L28: 0.05 | M28: 2 | N28: 1 | O28: 0.0059 | P28: 0.013 | Q28: Circular | R28: 3 | S28: 3 | T28: 0 | U28: 1273.32 | V28: 1278.55
A29: 206+53 RT. | B29: Curb Inlet | C29: on grade | D29: 204+67 RT. | E29: 0 | F29: 4 | G29: =H29*I29 -> 0 | H29: 0 | I29: 0 | K29: 0.02 | L29: 0.05 | M29: 2 | N29: 1 | O29: 0.0059 | P29: 0.013 | Q29: Circular | R29: 3 | S29: 3 | T29: 0 | U29: 1274.31 | V29: 1279.51
A30: 206+55 LT. | B30: Curb Inlet | C30: on grade | D30: 204+30 LT. | E30: 6 | F30: 4 | G30: =H30*I30 -> 0 | H30: 0 | I30: 0 | K30: 0.02 | L30: 0.05 | M30: 2 | N30: 1 | O30: 0.0059 | P30: 0.013 | Q30: Circular | R30: 6 | S30: 0 | T30: MO | U30: 1272.89 | V30: 1279.28
A31: 207+99 LT. | B31: Curb Inlet | C31: on grade | D31: 206+55 LT. | E31: 11 | F31: 4 | G31: =H31*I31 -> 0 | H31: 0 | I31: 0 | K31: 0.02 | L31: 0.05 | M31: 2 | N31: 1 | O31: 0.0059 | P31: 0.013 | Q31: Circular | R31: 11 | S31: 8 | T31: C | U31: 1273.64 | V31: 1279.78
A32: 208+17 RT. | B32: Curb Inlet | C32: on grade | D32: 206+53 RT. | E32: 4 | F32: 4 | G32: =H32*I32 -> 0 | H32: 0 | I32: 0 | K32: 0.02 | L32: 0.05 | M32: 2 | N32: 1 | O32: 0.0059 | P32: 0.013 | Q32: Circular | R32: 4 | S32: 0 | T32: MO | U32: 1275.44 | V32: 1280.48
A33: 208+65 RT. | B33: Grate Inlet | C33: on grade | D33: 208+17 RT. | E33: 4 | F33: 0 | G33: =H33*I33 -> 6 | H33: 2 | I33: 3 | K33: 0.02 | L33: 0.05 | M33: 0 | N33: 1 | O33: 0.0059 | P33: 0.013 | Q33: Rectangular | R33: 4 | S33: 4 | T33: ST | U33: 1275.75 | V33: 1280.02
A34: 208+98 LT. | B34: Curb Inlet | C34: on grade | D34: 207+99 LT. | E34: 7 | F34: 4 | G34: =H34*I34 -> 0 | H34: 0 | I34: 0 | K34: 0.02 | L34: 0.05 | M34: 2 | N34: 1 | O34: 0.0059 | P34: 0.013 | Q34: Circular | R34: 5 | S34: 7 | T34: C | U34: 1274.11 | V34: 1280.81
A35: 209+02 LT. | B35: Grate Inlet | C35: on grade | D35: 207+99 LT. | E35: 3 | F35: 0 | G35: =H35*I35 -> 6 | H35: 2 | I35: 3 | K35: 0.02 | L35: 0.05 | M35: 0 | N35: 1 | O35: 0.0378 | P35: 0.013 | Q35: Rectangular | R35: 3 | S35: 3 | T35: ST | U35: 1276.3 | V35: 1280.35
A36: 209+81 LT. | B36: Curb Inlet | C36: on grade | D36: 209+02 LT. | E36: 4 | F36: 4 | G36: =H36*I36 -> 0 | H36: 0 | I36: 0 | K36: 0.02 | L36: 0.05 | M36: 2 | N36: 1 | O36: 0.0378 | P36: 0.013 | Q36: Circular | R36: 4 | S36: 0 | T36: MO | U36: 1277.5 | V36: 1282.37
A37: 210+00 LT. | B37: Curb Inlet | C37: on grade | D37: 208+98 LT. | E37: 7 | F37: 4 | G37: =H37*I37 -> 0 | H37: 0 | I37: 0 | K37: 0.02 | L37: 0.05 | M37: 2 | N37: 1 | O37: 0.0378 | P37: 0.013 | Q37: Circular | R37: 7 | S37: 5 | T37: C | U37: 1274.64 | V37: 1281.18
A38: 210+51 LT. | B38: Grate Inlet | C38: sag | E38: 4 | F38: 0 | G38: =H38*I38 -> 6 | H38: 2 | I38: 3 | K38: 0.02 | L38: 0.05 | M38: 0 | N38: 1 | P38: 0.013 | Q38: Rectangular | R38: 4 | S38: 4 | T38: E | U38: 1276.74 | V38: 1283
A39: 210+60 RT. | B39: Curb Inlet | C39: on grade | D39: 113+00 RT. | E39: 4 | F39: 4 | G39: =H39*I39 -> 0 | H39: 0 | I39: 0 | K39: 0.02 | L39: 0.05 | M39: 2 | N39: 1 | O39: 0.0378 | P39: 0.013 | Q39: Circular | R39: 4 | S39: 0 | T39: MO | U39: 1279.4 | V39: 1284.82
A40: 211+00 LT. | B40: Curb Inlet | C40: on grade | D40: 210+00 LT. | E40: 4 | F40: 4 | G40: =H40*I40 -> 0 | H40: 0 | I40: 0 | K40: 0.02 | L40: 0.05 | M40: 2 | N40: 1 | O40: 0.0378 | P40: 0.013 | Q40: Circular | R40: 4 | S40: 0 | T40: MO | U40: 1278.74 | V40: 1285.46
...

Sheet Pipes
A1: Upstream | B1: Downstream | C1: Length | D1: Angle | E1: Type | F1: Q | G1: Drainage Area | H1: Runoff Coefficient | I1: Method | J1: Time of Concentration | K1: Invert Downstream | L1: Slope | M1: Invert Upstream | N1: Rise | O1: Type | P1: Span | Q1: Barrels | R1: n Value | S1: J-Loss | T1: Rim Downstream | U1: Rim Upstream
A2: 111+64 LT. | B2: 111+65 RT. | C2: 28 | D2: 0 | E2: Curb Inlet | F2: =7.5*G2*H2 -> 0.3 | G2: =MAX(ABS(VALUE(LEFT(SUBSTITUTE(A2,"+",""),5))-VALUE(LEFT(SUBSTITUTE(B2,"+",""),5)))*75/43560,0.05) -> 0.05 | H2: 0.8 | I2: Rational | J2: =MAX(SQRT(G2*43560)/0.5/30,5) -> 5 | K2: =LOOKUP(B2,Inlets!A:A,Inlets!U:U) -> 1274.47 | L2: =(M2-K2)/C2 -> 0.018928571 | M2: =LOOKUP(A2,Inlets!A:A,Inlets!U:U) -> 1275 | N2: 18 | O2: Circular | P2: =N2 -> 18 | Q2: 1 | R2: 0.013 | S2: 0.05 | T2: =LOOKUP(B2,Inlets!A:A,Inlets!V:V) -> 1279.07 | U2: =LOOKUP(A2,Inlets!A:A,Inlets!V:V) -> 1280
A3: 112+35 LT. | B3: 112+35 RT. | C3: 28 | D3: 0 | E3: Curb Inlet | F3: =7.5*G3*H3 -> 0.3 | G3: =MAX(ABS(VALUE(LEFT(SUBSTITUTE(A3,"+",""),5))-VALUE(LEFT(SUBSTITUTE(B3,"+",""),5)))*75/43560,0.05) -> 0.05 | H3: 0.8 | I3: Rational | J3: =MAX(SQRT(G3*43560)/0.5/30,5) -> 5 | K3: =LOOKUP(B3,Inlets!A:A,Inlets!U:U) -> 1275.14 | L3: =(M3-K3)/C3 -> 0.17357143 | M3: =LOOKUP(A3,Inlets!A:A,Inlets!U:U) -> 1280 | N3: 18 | O3: Circular | P3: =N3 -> 18 | Q3: 1 | R3: 0.013 | S3: 0.05 | T3: =LOOKUP(B3,Inlets!A:A,Inlets!V:V) -> 1279.48 | U3: =LOOKUP(A3,Inlets!A:A,Inlets!V:V) -> 1276
A4: 112+35 RT. | B4: 111+65 RT. | C4: 67 | D4: 0 | E4: Curb Inlet | F4: =7.5*G4*H4 -> 0.7231405 | G4: =MAX(ABS(VALUE(LEFT(SUBSTITUTE(A4,"+",""),5))-VALUE(LEFT(SUBSTITUTE(B4,"+",""),5)))*75/43560,0.05) -> 0.12052342 | H4: 0.8 | I4: Rational | J4: =MAX(SQRT(G4*43560)/0.5/30,5) -> 5 | K4: =LOOKUP(B4,Inlets!A:A,Inlets!U:U) -> 1274.47 | L4: =(M4-K4)/C4 -> 0.01 | M4: =LOOKUP(A4,Inlets!A:A,Inlets!U:U) -> 1275.14 | N4: 18 | O4: Circular | P4: =N4 -> 18 | Q4: 1 | R4: 0.013 | S4: 0.05 | T4: =LOOKUP(B4,Inlets!A:A,Inlets!V:V) -> 1279.07 | U4: =LOOKUP(A4,Inlets!A:A,Inlets!V:V) -> 1279.48
A5: 113+00 RT. | B5: 112+35 RT. | C5: 61 | D5: 0 | E5: Curb Inlet | F5: =7.5*G5*H5 -> 0.6714876 | G5: =MAX(ABS(VALUE(LEFT(SUBSTITUTE(A5,"+",""),5))-VALUE(LEFT(SUBSTITUTE(B5,"+",""),5)))*75/43560,0.05) -> 0.1119146 | H5: 0.8 | I5: Rational | J5: =MAX(SQRT(G5*43560)/0.5/30,5) -> 5 | K5: =LOOKUP(B5,Inlets!A:A,Inlets!U:U) -> 1275.14 | L5: =(M5-K5)/C5 -> 0.01 | M5: =LOOKUP(A5,Inlets!A:A,Inlets!U:U) -> 1275.75 | N5: 18 | O5: Circular | P5: =N5 -> 18 | Q5: 1 | R5: 0.013 | S5: 0.05 | T5: =LOOKUP(B5,Inlets!A:A,Inlets!V:V) -> 1279.48 | U5: =LOOKUP(A5,Inlets!A:A,Inlets!V:V) -> 1279.9
A6: 113+78 LT. | B6: 208+65 RT. | C6: 35 | D6: 0 | E6: Grate Inlet | F6: =7.5*G6*H6 -> 0.6 | G6: 0.1 | H6: 0.8 | I6: Rational | J6: =MAX(SQRT(G6*43560)/0.5/30,5) -> 5 | K6: =LOOKUP(B6,Inlets!A:A,Inlets!U:U) -> 1275.75 | L6: =(M6-K6)/C6 -> 0.0071428571 | M6: =LOOKUP(A6,Inlets!A:A,Inlets!U:U) -> 1276 | N6: 18 | O6: Circular | P6: =N6 -> 18 | Q6: 1 | R6: 0.013 | S6: 0.05 | T6: =LOOKUP(B6,Inlets!A:A,Inlets!V:V) -> 1280.02 | U6: =LOOKUP(A6,Inlets!A:A,Inlets!V:V) -> 1280.39
A7: 115+24 LT. | B7: 207+99 LT. | C7: 24 | D7: 0 | E7: Curb Inlet | F7: =7.5*G7*H7 -> 0.6 | G7: 0.1 | H7: 0.8 | I7: Rational | J7: =MAX(SQRT(G7*43560)/0.5/30,5) -> 5 | K7: =LOOKUP(B7,Inlets!A:A,Inlets!U:U) -> 1273.64 | L7: =(M7-K7)/C7 -> 0.019166667 | M7: =LOOKUP(A7,Inlets!A:A,Inlets!U:U) -> 1274.1 | N7: 18 | O7: Circular | P7: =N7 -> 18 | Q7: 1 | R7: 0.013 | S7: 0.05 | T7: =LOOKUP(B7,Inlets!A:A,Inlets!V:V) -> 1279.78 | U7: =LOOKUP(A7,Inlets!A:A,Inlets!V:V) -> 1279.63
A8: 115+42 LT. | B8: 115+24 LT. | C8: 17 | D8: 0 | E8: Grate Inlet | F8: =7.5*G8*H8 -> 0.3 | G8: =MAX(ABS(VALUE(LEFT(SUBSTITUTE(A8,"+",""),5))-VALUE(LEFT(SUBSTITUTE(B8,"+",""),5)))*75/43560,0.05) -> 0.05 | H8: 0.8 | I8: Rational | J8: =MAX(SQRT(G8*43560)/0.5/30,5) -> 5 | K8: =LOOKUP(B8,Inlets!A:A,Inlets!U:U) -> 1274.1 | L8: =(M8-K8)/C8 -> 0.10117647 | M8: =LOOKUP(A8,Inlets!A:A,Inlets!U:U) -> 1275.82 | N8: 18 | O8: Circular | P8: =N8 -> 18 | Q8: 1 | R8: 0.013 | S8: 0.05 | T8: =LOOKUP(B8,Inlets!A:A,Inlets!V:V) -> 1279.63 | U8: =LOOKUP(A8,Inlets!A:A,Inlets!V:V) -> 1279.4
A9: 115+66 LT. | B9: 115+24 LT. | C9: 52 | D9: 0 | E9: Curb Inlet | F9: =7.5*G9*H9 -> 0.4338843 | G9: =MAX(ABS(VALUE(LEFT(SUBSTITUTE(A9,"+",""),5))-VALUE(LEFT(SUBSTITUTE(B9,"+",""),5)))*75/43560,0.05) -> 0.07231405 | H9: 0.8 | I9: Rational | J9: =MAX(SQRT(G9*43560)/0.5/30,5) -> 5 | K9: =LOOKUP(B9,Inlets!A:A,Inlets!U:U) -> 1274.1 | L9: =(M9-K9)/C9 -> 0.019807692 | M9: =LOOKUP(A9,Inlets!A:A,Inlets!U:U) -> 1275.13 | N9: 18 | O9: Circular | P9: =N9 -> 18 | Q9: 1 | R9: 0.013 | S9: 0.05 | T9: =LOOKUP(B9,Inlets!A:A,Inlets!V:V) -> 1279.63 | U9: =LOOKUP(A9,Inlets!A:A,Inlets!V:V) -> 1280.24
A10: 115+90 RT. | B10: 210+00 LT. | C10: 21 | D10: 0 | E10: Curb Inlet | F10: =7.5*G10*H10 -> 0.6 | G10: 0.1 | H10: 0.8 | I10: Rational | J10: =MAX(SQRT(G10*43560)/0.5/30,5) -> 5 | K10: =LOOKUP(B10,Inlets!A:A,Inlets!U:U) -> 1274.64 | L10: =(M10-K10)/C10 -> 0.046666667 | M10: =LOOKUP(A10,Inlets!A:A,Inlets!U:U) -> 1275.62 | N10: 36 | O10: Circular | P10: =N10 -> 36 | Q10: 1 | R10: 0.013 | S10: 0.05 | T10: =LOOKUP(B10,Inlets!A:A,Inlets!V:V) -> 1281.18 | U10: =LOOKUP(A10,Inlets!A:A,Inlets!V:V) -> 1281.03
A11: 116+00 RT. | B11: 115+90 RT. | C11: 6 | D11: 0 | E11: Curb Inlet | F11: =7.5*G11*H11 -> 0.3 | G11: =MAX(ABS(VALUE(LEFT(SUBSTITUTE(A11,"+",""),5))-VALUE(LEFT(SUBSTITUTE(B11,"+",""),5)))*75/43560,0.05) -> 0.05 | H11: 0.8 | I11: Rational | J11: =MAX(SQRT(G11*43560)/0.5/30,5) -> 5 | K11: =LOOKUP(B11,Inlets!A:A,Inlets!U:U) -> 1275.62 | L11: =(M11-K11)/C11 -> 0.011666667 | M11: =LOOKUP(A11,Inlets!A:A,Inlets!U:U) -> 1275.69 | N11: 36 | O11: Circular | P11: =N11 -> 36 | Q11: 1 | R11: 0.013 | S11: 0.05 | T11: =LOOKUP(B11,Inlets!A:A,Inlets!V:V) -> 1281.03 | U11: =LOOKUP(A11,Inlets!A:A,Inlets!V:V) -> 1281.13
A12: 116+25 LT. | B12: 115+66 LT. | C12: 57 | D12: 0 | E12: Curb Inlet | F12: =7.5*G12*H12 -> 0.60950413 | G12: =MAX(ABS(VALUE(LEFT(SUBSTITUTE(A12,"+",""),5))-VALUE(LEFT(SUBSTITUTE(B12,"+",""),5)))*75/43560,0.05) -> 0.10158402 | H12: 0.8 | I12: Rational | J12: =MAX(SQRT(G12*43560)/0.5/30,5) -> 5 | K12: =LOOKUP(B12,Inlets!A:A,Inlets!U:U) -> 1275.13 | L12: =(M12-K12)/C12 -> 0.020701754 | M12: =LOOKUP(A12,Inlets!A:A,Inlets!U:U) -> 1276.31 | N12: 18 | O12: Circular | P12: =N12 -> 18 | Q12: 1 | R12: 0.013 | S12: 0.05 | T12: =LOOKUP(B12,Inlets!A:A,Inlets!V:V) -> 1280.24 | U12: =LOOKUP(A12,Inlets!A:A,Inlets!V:V) -> 1281.22
A13: 117+85 RT. | B13: 116+00 RT. | C13: 181 | D13: 0 | E13: Curb Inlet | F13: =7.5*G13*H13 -> 1.911157 | G13: =MAX(ABS(VALUE(LEFT(SUBSTITUTE(A13,"+",""),5))-VALUE(LEFT(SUBSTITUTE(B13,"+",""),5)))*75/43560,0.05) -> 0.31852617 | H13: 0.8 | I13: Rational | J13: =MAX(SQRT(G13*43560)/0.5/30,5) -> 7.8528127 | K13: =LOOKUP(B13,Inlets!A:A,Inlets!U:U) -> 1275.69 | L13: =(M13-K13)/C13 -> 0.012983425 | M13: =LOOKUP(A13,Inlets!A:A,Inlets!U:U) -> 1278.04 | N13: 36 | O13: Circular | P13: =N13 -> 36 | Q13: 1 | R13: 0.013 | S13: 0.05 | T13: =LOOKUP(B13,Inlets!A:A,Inlets!V:V) -> 1281.13 | U13: =LOOKUP(A13,Inlets!A:A,Inlets!V:V) -> 1283.99
A14: 118+25 LT. | B14: 116+25 LT. | C14: 196 | D14: 0 | E14: Curb Inlet | F14: =7.5*G14*H14 -> 2.0661157 | G14: =MAX(ABS(VALUE(LEFT(SUBSTITUTE(A14,"+",""),5))-VALUE(LEFT(SUBSTITUTE(B14,"+",""),5)))*75/43560,0.05) -> 0.34435262 | H14: 0.8 | I14: Rational | J14: =MAX(SQRT(G14*43560)/0.5/30,5) -> 8.1649658 | K14: =LOOKUP(B14,Inlets!A:A,Inlets!U:U) -> 1276.31 | L14: =(M14-K14)/C14 -> 0.020255102 | M14: =LOOKUP(A14,Inlets!A:A,Inlets!U:U) -> 1280.28 | N14: 18 | O14: Circular | P14: =N14 -> 18 | Q14: 1 | R14: 0.013 | S14: 0.05 | T14: =LOOKUP(B14,Inlets!A:A,Inlets!V:V) -> 1281.22 | U14: =LOOKUP(A14,Inlets!A:A,Inlets!V:V) -> 1284.45
A15: 120+50 LT. | B15: 118+25 LT. | C15: 221 | D15: 0 | E15: Curb Inlet | F15: =7.5*G15*H15 -> 2.3243802 | G15: =MAX(ABS(VALUE(LEFT(SUBSTITUTE(A15,"+",""),5))-VALUE(LEFT(SUBSTITUTE(B15,"+",""),5)))*75/43560,0.05) -> 0.38739669 | H15: 0.8 | I15: Rational | J15: =MAX(SQRT(G15*43560)/0.5/30,5) -> 8.660254 | K15: =LOOKUP(B15,Inlets!A:A,Inlets!U:U) -> 1280.28 | L15: =(M15-K15)/C15 -> 0.033438914 | M15: =LOOKUP(A15,Inlets!A:A,Inlets!U:U) -> 1287.67 | N15: 18 | O15: Circular | P15: =N15 -> 18 | Q15: 1 | R15: 0.013 | S15: 0.05 | T15: =LOOKUP(B15,Inlets!A:A,Inlets!V:V) -> 1284.45 | U15: =LOOKUP(A15,Inlets!A:A,Inlets!V:V) -> 1291.59
A16: 120+50 RT. | B16: 117+85 RT. | C16: 261 | D16: 0 | E16: Curb Inlet | F16: =7.5*G16*H16 -> 2.7376033 | G16: =MAX(ABS(VALUE(LEFT(SUBSTITUTE(A16,"+",""),5))-VALUE(LEFT(SUBSTITUTE(B16,"+",""),5)))*75/43560,0.05) -> 0.45626722 | H16: 0.8 | I16: Rational | J16: =MAX(SQRT(G16*43560)/0.5/30,5) -> 9.3985815 | K16: =LOOKUP(B16,Inlets!A:A,Inlets!U:U) -> 1278.04 | L16: =(M16-K16)/C16 -> 0.039157088 | M16: =LOOKUP(A16,Inlets!A:A,Inlets!U:U) -> 1288.26 | N16: 18 | O16: Circular | P16: =N16 -> 18 | Q16: 1 | R16: 0.013 | S16: 0.05 | T16: =LOOKUP(B16,Inlets!A:A,Inlets!V:V) -> 1283.99 | U16: =LOOKUP(A16,Inlets!A:A,Inlets!V:V) -> 1291.94
A17: 122+11 RT. | B17: 120+50 RT. | C17: 191 | D17: 0 | E17: Curb Inlet | F17: =7.5*G17*H17 -> 1.6632231 | G17: =MAX(ABS(VALUE(LEFT(SUBSTITUTE(A17,"+",""),5))-VALUE(LEFT(SUBSTITUTE(B17,"+",""),5)))*75/43560,0.05) -> 0.27720386 | H17: 0.8 | I17: Rational | J17: =MAX(SQRT(G17*43560)/0.5/30,5) -> 7.3257537 | K17: =LOOKUP(B17,Inlets!A:A,Inlets!U:U) -> 1288.26 | L17: =(M17-K17)/C17 -> 0.0091099476 | M17: =LOOKUP(A17,Inlets!A:A,Inlets!U:U) -> 1290 | N17: 18 | O17: Circular | P17: =N17 -> 18 | Q17: 1 | R17: 0.013 | S17: 0.05 | T17: =LOOKUP(B17,Inlets!A:A,Inlets!V:V) -> 1291.94 | U17: =LOOKUP(A17,Inlets!A:A,Inlets!V:V) -> 1295
A18: 124+50 LT. | B18: 120+50 LT. | C18: 396 | D18: 0 | E18: Curb Inlet | F18: =7.5*G18*H18 -> 4.1322314 | G18: =MAX(ABS(VALUE(LEFT(SUBSTITUTE(A18,"+",""),5))-VALUE(LEFT(SUBSTITUTE(B18,"+",""),5)))*75/43560,0.05) -> 0.68870523 | H18: 0.8 | I18: Rational | J18: =MAX(SQRT(G18*43560)/0.5/30,5) -> 11.547005 | K18: =LOOKUP(B18,Inlets!A:A,Inlets!U:U) -> 1287.67 | L18: =(M18-K18)/C18 -> 0.0077525253 | M18: =LOOKUP(A18,Inlets!A:A,Inlets!U:U) -> 1290.74 | N18: 18 | O18: Circular | P18: =N18 -> 18 | Q18: 1 | R18: 0.013 | S18: 0.05 | T18: =LOOKUP(B18,Inlets!A:A,Inlets!V:V) -> 1291.59 | U18: =LOOKUP(A18,Inlets!A:A,Inlets!V:V) -> 1294.35
A19: 200+19 LT. | B19: 200+19 RT. | C19: 61 | D19: 0 | E19: Curb Inlet | F19: =7.5*G19*H19 -> 0.3 | G19: =MAX(ABS(VALUE(LEFT(SUBSTITUTE(A19,"+",""),5))-VALUE(LEFT(SUBSTITUTE(B19,"+",""),5)))*75/43560,0.05) -> 0.05 | H19: 0.8 | I19: Rational | J19: =MAX(SQRT(G19*43560)/0.5/30,5) -> 5 | K19: =LOOKUP(B19,Inlets!A:A,Inlets!U:U) -> 1272.67 | L19: =(M19-K19)/C19 -> 0.072459016 | M19: =LOOKUP(A19,Inlets!A:A,Inlets!U:U) -> 1277.09 | N19: 18 | O19: Circular | P19: =N19 -> 18 | Q19: 1 | R19: 0.013 | S19: 0.05 | T19: =LOOKUP(B19,Inlets!A:A,Inlets!V:V) -> 1276.77 | U19: =LOOKUP(A19,Inlets!A:A,Inlets!V:V) -> 1280.64
A20: 200+19 RT. | B20: Outfall | C20: 226 | D20: 0 | E20: Curb Inlet | F20: =7.5*G20*H20 -> 0.3 | G20: 0.05 | H20: 0.8 | I20: Rational | J20: =MAX(SQRT(G20*43560)/0.5/30,5) -> 5 | K20: 1272 | L20: =(M20-K20)/C20 -> 0.0029646018 | M20: =LOOKUP(A20,Inlets!A:A,Inlets!U:U) -> 1272.67 | N20: 18 | O20: Circular | P20: =N20 -> 18 | Q20: 1 | R20: 0.013 | S20: 0.05 | T20: =LOOKUP(B20,Inlets!A:A,Inlets!V:V) -> 1289 | U20: =LOOKUP(A20,Inlets!A:A,Inlets!V:V) -> 1276.77
A21: 203+48 LT. | B21: 203+48 RT. | C21: 75 | D21: 0 | E21: Curb Inlet | F21: =7.5*G21*H21 -> 0.3 | G21: =MAX(ABS(VALUE(LEFT(SUBSTITUTE(A21,"+",""),5))-VALUE(LEFT(SUBSTITUTE(B21,"+",""),5)))*75/43560,0.05) -> 0.05 | H21: 0.8 | I21: Rational | J21: =MAX(SQRT(G21*43560)/0.5/30,5) -> 5 | K21: =LOOKUP(B21,Inlets!A:A,Inlets!U:U) -> 1271.2 | L21: =(M21-K21)/C21 -> 0.0046666667 | M21: =LOOKUP(A21,Inlets!A:A,Inlets!U:U) -> 1271.55 | N21: 40 | O21: Arch | P21: 65 | Q21: 1 | R21: 0.013 | S21: 0.05 | T21: =LOOKUP(B21,Inlets!A:A,Inlets!V:V) -> 1278.64 | U21: =LOOKUP(A21,Inlets!A:A,Inlets!V:V) -> 1278.44
A22: 203+48 RT. | B22: Outfall | C22: 50 | D22: 0 | E22: Curb Inlet | F22: =7.5*G22*H22 -> 0.3 | G22: 0.05 | H22: 0.8 | I22: Rational | J22: =MAX(SQRT(G22*43560)/0.5/30,5) -> 5 | K22: 1270 | L22: =(M22-K22)/C22 -> 0.024 | M22: =LOOKUP(A22,Inlets!A:A,Inlets!U:U) -> 1271.2 | N22: 54 | O22: Circular | P22: =N22 -> 54 | Q22: 1 | R22: 0.013 | S22: 0.05 | T22: =LOOKUP(B22,Inlets!A:A,Inlets!V:V) -> 1289 | U22: =LOOKUP(A22,Inlets!A:A,Inlets!V:V) -> 1278.64
A23: 204+09 RT. | B23: 203+48 RT. | C23: 55 | D23: 0 | E23: Curb Inlet | F23: =7.5*G23*H23 -> 0.63016529 | G23: =MAX(ABS(VALUE(LEFT(SUBSTITUTE(A23,"+",""),5))-VALUE(LEFT(SUBSTITUTE(B23,"+",""),5)))*75/43560,0.05) -> 0.10502755 | H23: 0.8 | I23: Rational | J23: =MAX(SQRT(G23*43560)/0.5/30,5) -> 5 | K23: =LOOKUP(B23,Inlets!A:A,Inlets!U:U) -> 1271.2 | L23: =(M23-K23)/C23 -> 0.032545455 | M23: =LOOKUP(A23,Inlets!A:A,Inlets!U:U) -> 1272.99 | N23: 24 | O23: Circular | P23: =N23 -> 24 | Q23: 1 | R23: 0.013 | S23: 0.05 | T23: =LOOKUP(B23,Inlets!A:A,Inlets!V:V) -> 1278.64 | U23: =LOOKUP(A23,Inlets!A:A,Inlets!V:V) -> 1278.53
A24: 204+20 LT. | B24: 203+48 LT. | C24: 65 | D24: 0 | E24: Curb Inlet | F24: =7.5*G24*H24 -> 0.74380165 | G24: =MAX(ABS(VALUE(LEFT(SUBSTITUTE(A24,"+",""),5))-VALUE(LEFT(SUBSTITUTE(B24,"+",""),5)))*75/43560,0.05) -> 0.12396694 | H24: 0.8 | I24: Rational | J24: =MAX(SQRT(G24*43560)/0.5/30,5) -> 5 | K24: =LOOKUP(B24,Inlets!A:A,Inlets!U:U) -> 1271.55 | L24: =(M24-K24)/C24 -> 0.0050769231 | M24: =LOOKUP(A24,Inlets!A:A,Inlets!U:U) -> 1271.88 | N24: 48 | O24: Circular | P24: =N24 -> 48 | Q24: 1 | R24: 0.013 | S24: 0.05 | T24: =LOOKUP(B24,Inlets!A:A,Inlets!V:V) -> 1278.44 | U24: =LOOKUP(A24,Inlets!A:A,Inlets!V:V) -> 1278.3
A25: 204+30 LT. | B25: 204+20 LT. | C25: 4 | D25: 0 | E25: Curb Inlet | F25: =7.5*G25*H25 -> 0.3 | G25: =MAX(ABS(VALUE(LEFT(SUBSTITUTE(A25,"+",""),5))-VALUE(LEFT(SUBSTITUTE(B25,"+",""),5)))*75/43560,0.05) -> 0.05 | H25: 0.8 | I25: Rational | J25: =MAX(SQRT(G25*43560)/0.5/30,5) -> 5 | K25: =LOOKUP(B25,Inlets!A:A,Inlets!U:U) -> 1271.88 | L25: =(M25-K25)/C25 -> 0.005 | M25: =LOOKUP(A25,Inlets!A:A,Inlets!U:U) -> 1271.9 | N25: 48 | O25: Circular | P25: =N25 -> 48 | Q25: 1 | R25: 0.013 | S25: 0.05 | T25: =LOOKUP(B25,Inlets!A:A,Inlets!V:V) -> 1278.3 | U25: =LOOKUP(A25,Inlets!A:A,Inlets!V:V) -> 1278.3
A26: 204+62 LT. | B26: 204+30 LT. | C26: 26 | D26: 0 | E26: Curb Inlet | F26: =7.5*G26*H26 -> 0.33057851 | G26: =MAX(ABS(VALUE(LEFT(SUBSTITUTE(A26,"+",""),5))-VALUE(LEFT(SUBSTITUTE(B26,"+",""),5)))*75/43560,0.05) -> 0.055096419 | H26: 0.8 | I26: Rational | J26: =MAX(SQRT(G26*43560)/0.5/30,5) -> 5 | K26: =LOOKUP(B26,Inlets!A:A,Inlets!U:U) -> 1271.9 | L26: =(M26-K26)/C26 -> 0.005 | M26: =LOOKUP(A26,Inlets!A:A,Inlets!U:U) -> 1272.03 | N26: 48 | O26: Circular | P26: =N26 -> 48 | Q26: 1 | R26: 0.013 | S26: 0.05 | T26: =LOOKUP(B26,Inlets!A:A,Inlets!V:V) -> 1278.3 | U26: =LOOKUP(A26,Inlets!A:A,Inlets!V:V) -> 1278.33
A27: 204+67 RT. | B27: 204+09 RT. | C27: 55 | D27: 0 | E27: Curb Inlet | F27: =7.5*G27*H27 -> 0.59917355 | G27: =MAX(ABS(VALUE(LEFT(SUBSTITUTE(A27,"+",""),5))-VALUE(LEFT(SUBSTITUTE(B27,"+",""),5)))*75/43560,0.05) -> 0.099862259 | H27: 0.8 | I27: Rational | J27: =MAX(SQRT(G27*43560)/0.5/30,5) -> 5 | K27: =LOOKUP(B27,Inlets!A:A,Inlets!U:U) -> 1272.99 | L27: =(M27-K27)/C27 -> 0.006 | M27: =LOOKUP(A27,Inlets!A:A,Inlets!U:U) -> 1273.32 | N27: 24 | O27: Circular | P27: =N27 -> 24 | Q27: 1 | R27: 0.013 | S27: 0.05 | T27: =LOOKUP(B27,Inlets!A:A,Inlets!V:V) -> 1278.53 | U27: =LOOKUP(A27,Inlets!A:A,Inlets!V:V) -> 1278.55
A28: 206+53 RT. | B28: 204+67 RT. | C28: 182 | D28: 0 | E28: Curb Inlet | F28: =7.5*G28*H28 -> 1.9214876 | G28: =MAX(ABS(VALUE(LEFT(SUBSTITUTE(A28,"+",""),5))-VALUE(LEFT(SUBSTITUTE(B28,"+",""),5)))*75/43560,0.05) -> 0.32024793 | H28: 0.8 | I28: Rational | J28: =MAX(SQRT(G28*43560)/0.5/30,5) -> 7.8740079 | K28: =LOOKUP(B28,Inlets!A:A,Inlets!U:U) -> 1273.32 | L28: =(M28-K28)/C28 -> 0.0054395604 | M28: =LOOKUP(A28,Inlets!A:A,Inlets!U:U) -> 1274.31 | N28: 24 | O28: Circular | P28: =N28 -> 24 | Q28: 1 | R28: 0.013 | S28: 0.05 | T28: =LOOKUP(B28,Inlets!A:A,Inlets!V:V) -> 1278.55 | U28: =LOOKUP(A28,Inlets!A:A,Inlets!V:V) -> 1279.51
A29: 206+55 LT | B29: 204+62 LT. | C29: 187 | D29: 0 | E29: Curb Inlet | F29: =7.5*G29*H29 -> 1.9938017 | G29: =MAX(ABS(VALUE(LEFT(SUBSTITUTE(A29,"+",""),5))-VALUE(LEFT(SUBSTITUTE(B29,"+",""),5)))*75/43560,0.05) -> 0.33230028 | H29: 0.8 | I29: Rational | J29: =MAX(SQRT(G29*43560)/0.5/30,5) -> 8.0208063 | K29: =LOOKUP(B29,Inlets!A:A,Inlets!U:U) -> 1272.03 | L29: =(M29-K29)/C29 -> 0.012192513 | M29: =LOOKUP(A29,Inlets!A:A,Inlets!U:U) -> 1274.31 | N29: 48 | O29: Circular | P29: =N29 -> 48 | Q29: 1 | R29: 0.013 | S29: 0.05 | T29: =LOOKUP(B29,Inlets!A:A,Inlets!V:V) -> 1278.33 | U29: =LOOKUP(A29,Inlets!A:A,Inlets!V:V) -> 1279.51
A30: 207+99 LT. | B30: 206+55 LT. | C30: 136 | D30: 0 | E30: Curb Inlet | F30: =7.5*G30*H30 -> 1.4876033 | G30: =MAX(ABS(VALUE(LEFT(SUBSTITUTE(A30,"+",""),5))-VALUE(LEFT(SUBSTITUTE(B30,"+",""),5)))*75/43560,0.05) -> 0.24793388 | H30: 0.8 | I30: Rational | J30: =MAX(SQRT(G30*43560)/0.5/30,5) -> 6.9282032 | K30: =LOOKUP(B30,Inlets!A:A,Inlets!U:U) -> 1272.89 | L30: =(M30-K30)/C30 -> 0.0055147059 | M30: =LOOKUP(A30,Inlets!A:A,Inlets!U:U) -> 1273.64 | N30: 48 | O30: Circular | P30: =N30 -> 48 | Q30: 1 | R30: 0.013 | S30: 0.05 | T30: =LOOKUP(B30,Inlets!A:A,Inlets!V:V) -> 1279.28 | U30: =LOOKUP(A30,Inlets!A:A,Inlets!V:V) -> 1279.78
A31: 208+17 RT. | B31: 206+53 RT. | C31: 20 | D31: 0 | E31: Grate Inlet | F31: =7.5*G31*H31 -> 1.6942149 | G31: =MAX(ABS(VALUE(LEFT(SUBSTITUTE(A31,"+",""),5))-VALUE(LEFT(SUBSTITUTE(B31,"+",""),5)))*75/43560,0.05) -> 0.28236915 | H31: 0.8 | I31: Rational | J31: =MAX(SQRT(G31*43560)/0.5/30,5) -> 7.393691 | K31: =LOOKUP(B31,Inlets!A:A,Inlets!U:U) -> 1274.31 | L31: =(M31-K31)/C31 -> 0.0565 | M31: =LOOKUP(A31,Inlets!A:A,Inlets!U:U) -> 1275.44 | N31: 18 | O31: Circular | P31: =N31 -> 18 | Q31: 1 | R31: 0.013 | S31: 0.05 | T31: =LOOKUP(B31,Inlets!A:A,Inlets!V:V) -> 1279.51 | U31: =LOOKUP(A31,Inlets!A:A,Inlets!V:V) -> 1280.48
A32: 208+22 RT. | B32: 206+53 RT. | C32: 165 | D32: 0 | E32: Curb Inlet | F32: =7.5*G32*H32 -> 1.7458678 | G32: =MAX(ABS(VALUE(LEFT(SUBSTITUTE(A32,"+",""),5))-VALUE(LEFT(SUBSTITUTE(B32,"+",""),5)))*75/43560,0.05) -> 0.29097796 | H32: 0.8 | I32: Rational | J32: =MAX(SQRT(G32*43560)/0.5/30,5) -> 7.5055535 | K32: =LOOKUP(B32,Inlets!A:A,Inlets!U:U) -> 1274.31 | L32: =(M32-K32)/C32 -> 0.0068484848 | M32: =LOOKUP(A32,Inlets!A:A,Inlets!U:U) -> 1275.44 | N32: 24 | O32: Circular | P32: =N32 -> 24 | Q32: 1 | R32: 0.013 | S32: 0.05 | T32: =LOOKUP(B32,Inlets!A:A,Inlets!V:V) -> 1279.51 | U32: =LOOKUP(A32,Inlets!A:A,Inlets!V:V) -> 1280.48
A33: 208+65 RT. | B33: 208+17 RT. | C33: 44 | D33: 0 | E33: Grate Inlet | F33: =7.5*G33*H33 -> 0.49586777 | G33: =MAX(ABS(VALUE(LEFT(SUBSTITUTE(A33,"+",""),5))-VALUE(LEFT(SUBSTITUTE(B33,"+",""),5)))*75/43560,0.05) -> 0.082644628 | H33: 0.8 | I33: Rational | J33: =MAX(SQRT(G33*43560)/0.5/30,5) -> 5 | K33: =LOOKUP(B33,Inlets!A:A,Inlets!U:U) -> 1275.44 | L33: =(M33-K33)/C33 -> 0.0070454545 | M33: =LOOKUP(A33,Inlets!A:A,Inlets!U:U) -> 1275.75 | N33: 18 | O33: Circular | P33: =N33 -> 18 | Q33: 1 | R33: 0.013 | S33: 0.05 | T33: =LOOKUP(B33,Inlets!A:A,Inlets!V:V) -> 1280.48 | U33: =LOOKUP(A33,Inlets!A:A,Inlets!V:V) -> 1280.02
A34: 208+98 LT. | B34: 207+99 LT. | C34: 89 | D34: 0 | E34: Curb Inlet | F34: =7.5*G34*H34 -> 1.0227273 | G34: =MAX(ABS(VALUE(LEFT(SUBSTITUTE(A34,"+",""),5))-VALUE(LEFT(SUBSTITUTE(B34,"+",""),5)))*75/43560,0.05) -> 0.17045455 | H34: 0.8 | I34: Rational | J34: =MAX(SQRT(G34*43560)/0.5/30,5) -> 5.7445626 | K34: =LOOKUP(B34,Inlets!A:A,Inlets!U:U) -> 1273.64 | L34: =(M34-K34)/C34 -> 0.0052808989 | M34: =LOOKUP(A34,Inlets!A:A,Inlets!U:U) -> 1274.11 | N34: 36 | O34: Arch | P34: 59 | Q34: 1 | R34: 0.013 | S34: 0.05 | T34: =LOOKUP(B34,Inlets!A:A,Inlets!V:V) -> 1279.78 | U34: =LOOKUP(A34,Inlets!A:A,Inlets!V:V) -> 1280.81
A35: 209+02 LT. | B35: 208+98 LT. | C35: 23 | D35: 0 | E35: Manhole | F35: =7.5*G35*H35 -> 0.3 | G35: =MAX(ABS(VALUE(LEFT(SUBSTITUTE(A35,"+",""),5))-VALUE(LEFT(SUBSTITUTE(B35,"+",""),5)))*75/43560,0.05) -> 0.05 | H35: 0.8 | I35: Rational | J35: =MAX(SQRT(G35*43560)/0.5/30,5) -> 5 | K35: =LOOKUP(B35,Inlets!A:A,Inlets!U:U) -> 1274.11 | L35: =(M35-K35)/C35 -> 0.095217391 | M35: =LOOKUP(A35,Inlets!A:A,Inlets!U:U) -> 1276.3 | N35: 18 | O35: Circular | P35: =N35 -> 18 | Q35: 1 | R35: 0.013 | S35: 0.05 | T35: =LOOKUP(B35,Inlets!A:A,Inlets!V:V) -> 1280.81 | U35: =LOOKUP(A35,Inlets!A:A,Inlets!V:V) -> 1280.35
A36: 209+81 LT. | B36: 209+02 LT. | C36: 75 | D36: 0 | E36: Curb Inlet | F36: =7.5*G36*H36 -> 0.8161157 | G36: =MAX(ABS(VALUE(LEFT(SUBSTITUTE(A36,"+",""),5))-VALUE(LEFT(SUBSTITUTE(B36,"+",""),5)))*75/43560,0.05) -> 0.13601928 | H36: 0.8 | I36: Rational | J36: =MAX(SQRT(G36*43560)/0.5/30,5) -> 5.1316014 | K36: =LOOKUP(B36,Inlets!A:A,Inlets!U:U) -> 1276.3 | L36: =(M36-K36)/C36 -> 0.016 | M36: =LOOKUP(A36,Inlets!A:A,Inlets!U:U) -> 1277.5 | N36: 18 | O36: Circular | P36: =N36 -> 18 | Q36: 1 | R36: 0.013 | S36: 0.05 | T36: =LOOKUP(B36,Inlets!A:A,Inlets!V:V) -> 1280.35 | U36: =LOOKUP(A36,Inlets!A:A,Inlets!V:V) -> 1282.37
A37: 210+00 LT. | B37: 208+98 LT. | C37: 106 | D37: 0 | E37: Curb Inlet | F37: =7.5*G37*H37 -> 1.053719 | G37: =MAX(ABS(VALUE(LEFT(SUBSTITUTE(A37,"+",""),5))-VALUE(LEFT(SUBSTITUTE(B37,"+",""),5)))*75/43560,0.05) -> 0.17561983 | H37: 0.8 | I37: Rational | J37: =MAX(SQRT(G37*43560)/0.5/30,5) -> 5.8309519 | K37: =LOOKUP(B37,Inlets!A:A,Inlets!U:U) -> 1274.11 | L37: =(M37-K37)/C37 -> 0.005 | M37: =LOOKUP(A37,Inlets!A:A,Inlets!U:U) -> 1274.64 | N37: 36 | O37: Arch | P37: 59 | Q37: 1 | R37: 0.013 | S37: 0.05 | T37: =LOOKUP(B37,Inlets!A:A,Inlets!V:V) -> 1280.81 | U37: =LOOKUP(A37,Inlets!A:A,Inlets!V:V) -> 1281.18
A38: 210+51 LT. | B38: 210+00 LT. | C38: 47 | D38: 0 | E38: Grate Inlet | F38: =7.5*G38*H38 -> 0.5268595 | G38: =MAX(ABS(VALUE(LEFT(SUBSTITUTE(A38,"+",""),5))-VALUE(LEFT(SUBSTITUTE(B38,"+",""),5)))*75/43560,0.05) -> 0.087809917 | H38: 0.8 | I38: Rational | J38: =MAX(SQRT(G38*43560)/0.5/30,5) -> 5 | K38: =LOOKUP(B38,Inlets!A:A,Inlets!U:U) -> 1274.64 | L38: =(M38-K38)/C38 -> 0.044680851 | M38: =LOOKUP(A38,Inlets!A:A,Inlets!U:U) -> 1276.74 | N38: 18 | O38: Circular | P38: =N38 -> 18 | Q38: 1 | R38: 0.013 | S38: 0.05 | T38: =LOOKUP(B38,Inlets!A:A,Inlets!V:V) -> 1281.18 | U38: =LOOKUP(A38,Inlets!A:A,Inlets!V:V) -> 1283
A39: 210+60 RT. | B39: 208+65 RT. | C39: 194 | D39: 0 | E39: Curb Inlet | F39: =7.5*G39*H39 -> 2.0144628 | G39: =MAX(ABS(VALUE(LEFT(SUBSTITUTE(A39,"+",""),5))-VALUE(LEFT(SUBSTITUTE(B39,"+",""),5)))*75/43560,0.05) -> 0.3357438 | H39: 0.8 | I39: Rational | J39: =MAX(SQRT(G39*43560)/0.5/30,5) -> 8.0622577 | K39: =LOOKUP(B39,Inlets!A:A,Inlets!U:U) -> 1275.75 | L39: =(M39-K39)/C39 -> 0.018814433 | M39: =LOOKUP(A39,Inlets!A:A,Inlets!U:U) -> 1279.4 | N39: 18 | O39: Circular | P39: =N39 -> 18 | Q39: 1 | R39: 0.013 | S39: 0.05 | T39: =LOOKUP(B39,Inlets!A:A,Inlets!V:V) -> 1280.02 | U39: =LOOKUP(A39,Inlets!A:A,Inlets!V:V) -> 1284.82
A40: 211+00 LT. | B40: 210+51 LT. | C40: 56 | D40: 0 | E40: Curb Inlet | F40: =7.5*G40*H40 -> 0.50619835 | G40: =MAX(ABS(VALUE(LEFT(SUBSTITUTE(A40,"+",""),5))-VALUE(LEFT(SUBSTITUTE(B40,"+",""),5)))*75/43560,0.05) -> 0.084366391 | H40: 0.8 | I40: Rational | J40: =MAX(SQRT(G40*43560)/0.5/30,5) -> 5 | K40: =LOOKUP(B40,Inlets!A:A,Inlets!U:U) -> 1276.74 | L40: =(M40-K40)/C40 -> 0.035714286 | M40: =LOOKUP(A40,Inlets!A:A,Inlets!U:U) -> 1278.74 | N40: 18 | O40: Circular | P40: =N40 -> 18 | Q40: 1 | R40: 0.013 | S40: 0.05 | T40: =LOOKUP(B40,Inlets!A:A,Inlets!V:V) -> 1283 | U40: =LOOKUP(A40,Inlets!A:A,Inlets!V:V) -> 1285.46
...
